raceback (most recent call last):
  File "c:\Users\AD39644\Desktop\EIS\OneDrive_2024-07-25\Auditing Script\Visualizor.py", line 454, in <module>
    main()
  File "c:\Users\AD39644\Desktop\EIS\OneDrive_2024-07-25\Auditing Script\Visualizor.py", line 445, in main
    {generate_lec_tab(df)}
     ^^^^^^^^^^^^^^^^^^^^
  File "c:\Users\AD39644\Desktop\EIS\OneDrive_2024-07-25\Auditing Script\Visualizor.py", line 277, in generate_lec_tab      
    lec_final = lec_filtered.append(pd.Series({"Misc. LECs": misc_total}))
                ^^^^^^^^^^^^^^^^^^^
  File "C:\Users\AD39644\Desktop\EIS\OneDrive_2024-07-25\Auditing Script\.venv\Lib\site-packages\pandas\core\generic.py", line 6299, in __getattr__
    return object.__getattribute__(self, name)
           ^^^^^^^^^^^^^^^^^^^^^^^^^^^^^^^^^^^
AttributeError: 'Series' object has no attribute 'append'. Did you mean: '_append'?
PS C:\Users\AD39644\Desktop\EIS\OneDrive_2024-07-25\Auditing Script> & "c:/Users/AD39644/Desktop/EIS/OneDrive_2024-07-25/Auditing Script/.venv/Scripts/python.exe" "c:/Users/AD39644/Desktop/EIS/OneDrive_2024-07-25/Auditing Script/Visualizor.py"
Column headers: ['Data Source', 'Customer Name', 'Product Category', 'Case/Task ID', 'TASK_INSTANCE_ID (FlightDeck)', 'Task Name', 'Status', 'Create Date', 'Completed Date', 'Task Owner', 'VP (from Owner)', 'Director (from Owner)', 'Manager (from Owner)', 'Originator', 'VP (from Originator)', 'Director (from Originator)', 'Manager (from Originator)', 'Product Name', 'Subtype', 'Subtype Detail', 'Task Interval (Day)', 'Task Interval (Hour)', 'Service Identifier', 'MRR', 'Closure Code 1', 'Closure Code 2', 'Closure Code 3', 'Closure Code 4', 'Closure Code 5', 'Complete Remarks', 'SOU', 'Workgroup Name', 'PID', 'LEC', 'Revised LEC', 'Month', 'Is Fail']
Traceback (most recent call last):
  File "c:\Users\\Desktop\EIS\OneDrive_2024-07-25\Auditing Script\Visualizor.py", line 454, in <module>
    main()
  File "c:\Users\\Desktop\EIS\OneDrive_2024-07-25\Auditing Script\Visualizor.py", line 445, in main
    {generate_lec_tab(df)}
     ^^^^^^^^^^^^^^^^^^^^
  File "c:\Users\\Desktop\EIS\OneDrive_2024-07-25\Auditing Script\Visualizor.py", line 278, in generate_lec_tab      
    lec_total_pie = px.pie(
                    ^^^^^^^
  File "C:\Users\\Desktop\EIS\OneDrive_2024-07-25\Auditing Script\.venv\Lib\site-packages\plotly\express\_chart_types.py", line 1701, in pie
    return make_figure(
           ^^^^^^^^^^^^
  File "C:\Users\\Desktop\EIS\OneDrive_2024-07-25\Auditing Script\.venv\Lib\site-packages\plotly\express\_core.py", line 2483, in make_figure
    args = build_dataframe(args, constructor)
           ^^^^^^^^^^^^^^^^^^^^^^^^^^^^^^^^^^
  File "C:\Users\\Desktop\EIS\OneDrive_2024-07-25\Auditing Script\.venv\Lib\site-packages\plotly\express\_core.py", line 1729, in build_dataframe
    df_output, wide_id_vars = process_args_into_dataframe(
                              ^^^^^^^^^^^^^^^^^^^^^^^^^^^^
  File "C:\Users\AD39644\Desktop\EIS\OneDrive_2024-07-25\Auditing Script\.venv\Lib\site-packages\plotly\express\_core.py", line 1330, in process_args_into_dataframe
    raise ValueError(err_msg)
ValueError: Value of 'values' is not the name of a column in 'data_frame'. Expected one of ['index', 0] but received: Revised LEC
