
   with open(output_path, 'w') as file:
         ^^^^^^^^^^^^^^^^^^^^^^
FileNotFoundError: [Errno 2] No such file or directory: 'C:\\Users\\a\\30719746/30719738/ 31049671 - 2025-02-28 - Pre-Checks.txt'

During handling of the above exception, another exception occurred:

Traceback (most recent call last):
  File "c:\Users\a\Desktop\EIS\OneDrive_2024-07-25\Auditing Script\IPv6 Config Generator.py", line 352, in <module>
    with open(output_path, 'w') as file:
         ^^^^^^^^^^^^^^^^^^^^^^
FileNotFoundError: [Errno 2] No such file or directory: 'C:\\Users\\AD39644\\30719746/30719738/ 31049671 - 2025-02-28 - Pre-Checks.txt'
